Workbook
Name Bảng_lương: 'Estimated Sale'!$E$6:$E$11

Sheet Start-Up Investment
B2: Start-Up Investment (Unit: VND) | M2: Start-Up Investment (Unit: VND)
B3: Capital expenditure (CAPEX) | M3: Capital expenditure | N3: =G14 -> 63000000
B4: No. | C4: Item | D4: Unit | E4: Quantity | F4: Cost/unit | G4: Total | H4: Role | I4: Note | M4: Working Capital Investment | N4: =G19 -> 205000000
B5: 1 | C5: CÔNG NGHỆ VÀ MÁY MÓC | G5: =F5*E5 -> 0 | M5: Other Investment | N5: =G33 -> 25267000
C6: Website E-commerce | D6: Item | E6: 1 | F6: 20000000 | G6: =F6*E6 -> 20000000 | H6: Cửa hàng chính, nơi khách xem và đặt hàng | I6: Giao diện chuẩn SEO, tích hợp thanh toán, quản lý đơn hàng | M6: Total Investment | N6: =N3+N4+N5 -> 293267000
C7: Máy in đơn hàng | D7: Item | E7: 2 | F7: 1000000 | G7: =F7*E7 -> 2000000 | H7: In vận đơn
B8: 2 | C8: STUDIO | G8: =F8*E8 -> 0
C9: Máy ảnh | D9: Item | E9: 1 | F9: 20000000 | G9: =F9*E9 -> 20000000 | H9: Chụp ảnh sản phẩm đăng bán | I9: Độ phân giải cao, lấy nét tốt, ưu tiên dòng có màu sắc thực
C10: Đèn Studio (Softbox) | D10: Item | E10: 3 | F10: 2000000 | G10: =F10*E10 -> 6000000 | H10: Tạo ánh sáng ổn định, rõ chi tiết vải | I10: Ánh sáng trắng (5500K), có thể điều chỉnh độ sáng
C11: Phông nền (Background) | D11: Set | E11: 1 | F11: 5000000 | G11: =F11*E11 -> 5000000 | H11: Làm nổi bật màu sắc quần áo | I11: Vải hoặc giấy màu trung tính (trắng/xám/be), không nhăn
B12: 3 | C12: CHI PHÍ KHÁC | G12: =F12*E12 -> 0
C13: Tài sản khác | D13: n/a | E13: 1 | F13: 10000000 | G13: =F13*E13 -> 10000000
B14: Total CAPEX | G14: =SUM(G5:G13) -> 63000000
B15: Working Capital Investment
B16: No. | C16: Item | D16: Unit | E16: Quantity | F16: Cost/unit | G16: Total
B17: 1 | C17: Cash | D17: n/a | E17: 1 | F17: 200000000 | G17: =F17*E17 -> 200000000
B18: 2 | C18: Supplies | D18: n/a | E18: 1 | F18: 5000000 | G18: =F18*E18 -> 5000000
B19: Total Working Capital Investment | G19: =SUM(G17:G18) -> 205000000
B20: Other Investment
B21: No. | C21: Item | D21: Unit | E21: Quantity | F21: Cost/unit | G21: Total
B22: 1 | C22: Legal Procedure
C23: Trademark registration | D23: Item | E23: 1 | F23: 1270000 | G23: =F23*E23 -> 1270000
C24: Tax code fee | D24: Item | E24: 1 | F24: 1200000 | G24: =F24*E24 -> 1200000
C25: Intellectual property registration | D25: Item | E25: 1 | F25: 1080000 | G25: =F25*E25 -> 1080000
C26: Business registration | D26: Year | E26: 1 | F26: 2000000 | G26: =F26*E26 -> 2000000
C27: Digital signature | D27: Item | E27: 1 | F27: 1067000 | G27: =F27*E27 -> 1067000
C28: Company seal & seal registration | D28: Item | E28: 1 | F28: 450000 | G28: =F28*E28 -> 450000
C29: Public information disclosure fee on national portal | D29: Item | E29: 1 | F29: 200000 | G29: =F29*E29 -> 200000
C30: Invoice issuance fee | D30: Year | E30: 1 | F30: 5000000 | G30: =F30*E30 -> 5000000
B31: 2 | C31: The brand identity | D31: n/a | E31: 1 | F31: 5000000 | G31: =F31*E31 -> 5000000
B32: 3 | C32: Rent deposit | D32: Month | E32: 1 | F32: 8000000 | G32: =F32*E32 -> 8000000 | I32: TIKTAK COWORKING SPACE Hotline: 0898.580.666 Email: booking@tiktak.com.vn Website: https://tiktak.com.vn/ Địa chỉ: TIKTAK 1: Tầng 5, Toà nhà Diamond Flower Tower, số 1 Hoàng Đạo Thúy, Phường Thanh Xuân, Hà Nội TIKTAK 2: Tầng 12, Tòa nhà Hồng Hà Center, số 25 Lý Thường Kiệt, Phường Cửa Nam, Hà Nội
B33: Total Other Investment | G33: =SUM(G22:G32) -> 25267000

Sheet Depreciation Expenses
B2: Depreciation and allocation of Capital Expenditure Investment (Unit: VND)
B3: No. | C3: Capital assets | D3: Cost | E3: Estimated Useful life (year) | F3: Salvage Value | G3: Depreciation and allocation expenses per year
G4: Year 1 | H4: Year 2 | I4: Year 3 | J4: Year 4
B5: 1 | C5: ='Start-Up Investment'!C5 -> CÔNG NGHỆ VÀ MÁY MÓC | F5: 0
C6: ='Start-Up Investment'!C6 -> Website E-commerce | D6: ='Start-Up Investment'!G6 -> 20000000 | E6: 3 | F6: 0 | G6: =D6/E6 -> 6666666.7 | H6: =G6 -> 6666666.7 | I6: =H6 -> 6666666.7
C7: ='Start-Up Investment'!C7 -> Máy in đơn hàng | D7: ='Start-Up Investment'!G7 -> 2000000 | E7: 1 | F7: 0 | G7: =D7/E7 -> 2000000
B8: 2 | C8: ='Start-Up Investment'!C8 -> STUDIO | D8: ='Start-Up Investment'!G8 -> 0 | F8: 0 | H8: =IF(E8>1,G8,0) -> 0 | I8: =IF(E8>2,H8,0) -> 0 | J8: =IF(E8>3,I8,0) -> 0
C9: ='Start-Up Investment'!C9 -> Máy ảnh | D9: ='Start-Up Investment'!G9 -> 20000000 | E9: 3 | F9: 0 | G9: =D9/E9 -> 6666666.7 | H9: =G9 -> 6666666.7 | I9: =H9 -> 6666666.7
C10: ='Start-Up Investment'!C10 -> Đèn Studio (Softbox) | D10: ='Start-Up Investment'!G10 -> 6000000 | E10: 2 | F10: 0 | G10: =D10/E10 -> 3000000 | H10: =G10 -> 3000000 | J10: =IF(E10>3,I10,0) -> 0
C11: ='Start-Up Investment'!C11 -> Phông nền (Background) | D11: ='Start-Up Investment'!G11 -> 5000000 | E11: 2 | F11: 0 | G11: =D11/E11/2 -> 1250000 | H11: =G11*2 -> 2500000 | I11: =G11 -> 1250000 | J11: =IF(E11>3,I11,0) -> 0
B12: 3 | C12: ='Start-Up Investment'!C12 -> CHI PHÍ KHÁC | D12: ='Start-Up Investment'!G12 -> 0 | F12: 0 | H12: =IF(E12>1,G12,0) -> 0 | I12: =IF(E12>2,H12,0) -> 0 | J12: =IF(E12>3,I12,0) -> 0
C13: ='Start-Up Investment'!C13 -> Tài sản khác | D13: ='Start-Up Investment'!G13 -> 10000000 | E13: 2 | F13: 0 | G13: =D13/E13 -> 5000000 | H13: =G13 -> 5000000
B14: Total Depreciation and allocation expenses | F14: =SUM(F5:F13) -> 0 | G14: =SUM(G5:G13) -> 24583333 | H14: =SUM(H5:H13) -> 23833333 | I14: =SUM(I5:I13) -> 14583333 | J14: =SUM(J5:J13) -> 0

Sheet BOM
B2: Bill of Materials
B3: No | C3: Product | D3: Chi phí gia công | E3: Chi phí bao bì & Vật tư | I3: Total Cosg per unit
E4: Túi Zip khóa kéo in Logo | F4: Túi niêm phong (Poly Mailer) | G4: Thẻ cảm ơn & Sticker tặng kèm | H4: Giấy in nhiệt & Băng keo
B5: 1 | C5: Áo phông | D5: 110000 | E5: 2500 | F5: 1500 | G5: 3000 | H5: 1000 | I5: =SUM(D5:H5) -> 118000
B6: 2 | C6: Áo hudy | D6: 130000 | E6: 2500 | F6: 1500 | G6: 3000 | H6: 1000 | I6: =SUM(D6:H6) -> 138000
B7: 3 | C7: Móc khoá | D7: 5000 | E7: 0 | F7: 500 | G7: 3000 | H7: 1000 | I7: =SUM(D7:H7) -> 9500
B8: 4 | C8: Mũ | D8: 10000 | E8: 1000 | F8: 500 | G8: 3000 | H8: 1000 | I8: =SUM(D8:H8) -> 15500
B9: 5 | C9: Tất | D9: 5000 | E9: 0 | F9: 500 | G9: 3000 | H9: 1000 | I9: =SUM(D9:H9) -> 9500
B10: 6 | C10: Áo bomber | D10: 150000 | E10: 2500 | F10: 1500 | G10: 3000 | H10: 1000 | I10: =SUM(D10:H10) -> 158000

Sheet Price setting
B2: Price setting
B3: No | C3: Product | D3: Price | E3: COGS
B4: 1 | C4: Áo phông | D4: 250000 | E4: =BOM!I5 -> 118000
B5: 2 | C5: Áo hoodie | D5: 280000 | E5: =BOM!I6 -> 138000
B6: 3 | C6: Móc khoá | D6: 15000 | E6: =BOM!I7 -> 9500
B7: 4 | C7: Mũ | D7: 45000 | E7: =BOM!I8 -> 15500
B8: 5 | C8: Tất | D8: 20000 | E8: =BOM!I9 -> 9500
B9: 6 | C9: Áo bomber | D9: 320000 | E9: =BOM!I10 -> 158000

Sheet Insurance Structure
B2: Insurance
B3: Detail | E3: Total
B4: Social insurance | C4: Health insurance | D4: Unemployment insurance
B5: 0.175 | C5: 0.03 | D5: 0.01 | E5: =SUM(B5:D5) -> 0.215

Sheet Marketing Expenses
A1: Marketing Expenses
A2: Detail | B2: % Total Marketing Expenses | C2: Year 1 | O2: Full Year
C3: Jan | D3: Feb | E3: Mar | F3: Apr | G3: May | H3: Jun | I3: Jul | J3: Aug | K3: Sep | L3: Oct | M3: Nov | N3: Dec
A4: Total Marketing Expenses | C4: ='Operating Expenses'!#REF! -> #REF! | D4: ='Operating Expenses'!#REF! -> #REF! | E4: ='Operating Expenses'!#REF! -> #REF! | F4: ='Operating Expenses'!#REF! -> #REF! | G4: ='Operating Expenses'!#REF! -> #REF! | H4: ='Operating Expenses'!#REF! -> #REF! | I4: ='Operating Expenses'!#REF! -> #REF! | J4: ='Operating Expenses'!#REF! -> #REF! | ... M4: ='Operating Expenses'!#REF! -> #REF! | N4: ='Operating Expenses'!D13 -> 31893000 | O4: =SUM(C4:N4) -> #REF!
A5: Advertising | C5: =C4*$B$5 -> #REF! | D5: =D4*$B$5 -> #REF! | E5: =E4*$B$5 -> #REF! | F5: =F4*$B$5 -> #REF! | G5: =G4*$B$5 -> #REF! | H5: =H4*$B$5 -> #REF! | I5: =I4*$B$5 -> #REF! | J5: =J4*$B$5 -> #REF! | ... N5: =N4*$B$5 -> 0 | O5: =SUM(C5:N5) -> #REF!
A6: Public relations | C6: =C4*$B$6 -> #REF! | D6: =D4*$B$6 -> #REF! | E6: =E4*$B$6 -> #REF! | F6: =F4*$B$6 -> #REF! | G6: =G4*$B$6 -> #REF! | H6: =H4*$B$6 -> #REF! | I6: =I4*$B$6 -> #REF! | J6: =J4*$B$6 -> #REF! | ... N6: =N4*$B$6 -> 0 | O6: =SUM(C6:N6) -> #REF!
A7: Sales promotion | C7: =C4*$B$7 -> #REF! | D7: =D4*$B$7 -> #REF! | E7: =E4*$B$7 -> #REF! | F7: =F4*$B$7 -> #REF! | G7: =G4*$B$7 -> #REF! | H7: =H4*$B$7 -> #REF! | I7: =I4*$B$7 -> #REF! | J7: =J4*$B$7 -> #REF! | ... N7: =N4*$B$7 -> 0 | O7: =SUM(C7:N7) -> #REF!
A8: Direct marketing | C8: =C4*$B$8 -> #REF! | D8: =D4*$B$8 -> #REF! | E8: =E4*$B$8 -> #REF! | F8: =F4*$B$8 -> #REF! | G8: =G4*$B$8 -> #REF! | H8: =H4*$B$8 -> #REF! | I8: =I4*$B$8 -> #REF! | J8: =J4*$B$8 -> #REF! | ... N8: =N4*$B$8 -> 0 | O8: =SUM(C8:N8) -> #REF!
A9: Personal selling | C9: =C4*$B$9 -> #REF! | D9: =D4*$B$9 -> #REF! | E9: =E4*$B$9 -> #REF! | F9: =F4*$B$9 -> #REF! | G9: =G4*$B$9 -> #REF! | H9: =H4*$B$9 -> #REF! | I9: =I4*$B$9 -> #REF! | J9: =J4*$B$9 -> #REF! | ... N9: =N4*$B$9 -> 0 | O9: =SUM(C9:N9) -> #REF!
A11: Detail | B11: % Total Marketing Expenses | C11: Year 2 | O11: Full Year
C12: Jan | D12: Feb | E12: Mar | F12: Apr | G12: May | H12: Jun | I12: Jul | J12: Aug | K12: Sep | L12: Oct | M12: Nov | N12: Dec
A13: Total Marketing Expenses | C13: ='Operating Expenses'!#REF! -> #REF! | D13: ='Operating Expenses'!#REF! -> #REF! | E13: ='Operating Expenses'!#REF! -> #REF! | F13: ='Operating Expenses'!#REF! -> #REF! | G13: ='Operating Expenses'!#REF! -> #REF! | H13: ='Operating Expenses'!#REF! -> #REF! | I13: ='Operating Expenses'!#REF! -> #REF! | J13: ='Operating Expenses'!#REF! -> #REF! | ... M13: ='Operating Expenses'!#REF! -> #REF! | N13: ='Operating Expenses'!F13 -> 39687750 | O13: =SUM(C13:N13) -> #REF!
A14: Advertising | B14: 0.3 | C14: =C13*$B$14 -> #REF! | D14: =D13*$B$14 -> #REF! | E14: =E13*$B$14 -> #REF! | F14: =F13*$B$14 -> #REF! | G14: =G13*$B$14 -> #REF! | H14: =H13*$B$14 -> #REF! | I14: =I13*$B$14 -> #REF! | J14: =J13*$B$14 -> #REF! | ... N14: =N13*$B$14 -> 11906325 | O14: =SUM(C14:N14) -> #REF!
A15: Public relations | B15: 0.15 | C15: =C13*$B$15 -> #REF! | D15: =D13*$B$15 -> #REF! | E15: =E13*$B$15 -> #REF! | F15: =F13*$B$15 -> #REF! | G15: =G13*$B$15 -> #REF! | H15: =H13*$B$15 -> #REF! | I15: =I13*$B$15 -> #REF! | J15: =J13*$B$15 -> #REF! | ... N15: =N13*$B$15 -> 5953162.5 | O15: =SUM(C15:N15) -> #REF!
A16: Sales promotion | B16: 0.15 | C16: =C13*$B$16 -> #REF! | D16: =D13*$B$16 -> #REF! | E16: =E13*$B$16 -> #REF! | F16: =F13*$B$16 -> #REF! | G16: =G13*$B$16 -> #REF! | H16: =H13*$B$16 -> #REF! | I16: =I13*$B$16 -> #REF! | J16: =J13*$B$16 -> #REF! | ... N16: =N13*$B$16 -> 5953162.5 | O16: =SUM(C16:N16) -> #REF!
A17: Direct marketing | B17: 0.2 | C17: =C13*$B$17 -> #REF! | D17: =D13*$B$17 -> #REF! | E17: =E13*$B$17 -> #REF! | F17: =F13*$B$17 -> #REF! | G17: =G13*$B$17 -> #REF! | H17: =H13*$B$17 -> #REF! | I17: =I13*$B$17 -> #REF! | J17: =J13*$B$17 -> #REF! | ... N17: =N13*$B$17 -> 7937550 | O17: =SUM(C17:N17) -> #REF!
A18: Personal selling | B18: 0.2 | C18: =C13*$B$18 -> #REF! | D18: =D13*$B$18 -> #REF! | E18: =E13*$B$18 -> #REF! | F18: =F13*$B$18 -> #REF! | G18: =G13*$B$18 -> #REF! | H18: =H13*$B$18 -> #REF! | I18: =I13*$B$18 -> #REF! | J18: =J13*$B$18 -> #REF! | ... N18: =N13*$B$18 -> 7937550 | O18: =SUM(C18:N18) -> #REF!
B20: % Total Marketing Expenses | C20: Year 3 | O20: Full Year
C21: Jan | D21: Feb | E21: Mar | F21: Apr | G21: May | H21: Jun | I21: Jul | J21: Aug | K21: Sep | L21: Oct | M21: Nov | N21: Dec
A22: Total Marketing Expenses | C22: ='Operating Expenses'!#REF! -> #REF! | D22: ='Operating Expenses'!#REF! -> #REF! | E22: ='Operating Expenses'!#REF! -> #REF! | F22: ='Operating Expenses'!#REF! -> #REF! | G22: ='Operating Expenses'!#REF! -> #REF! | H22: ='Operating Expenses'!#REF! -> #REF! | I22: ='Operating Expenses'!#REF! -> #REF! | J22: ='Operating Expenses'!#REF! -> #REF! | ... M22: ='Operating Expenses'!#REF! -> #REF! | N22: ='Operating Expenses'!H13 -> 36474000 | O22: =SUM(C22:N22) -> #REF!
A23: Advertising | B23: 0.3 | C23: =C22*$B$23 -> #REF! | D23: =D22*$B$23 -> #REF! | E23: =E22*$B$23 -> #REF! | F23: =F22*$B$23 -> #REF! | G23: =G22*$B$23 -> #REF! | H23: =H22*$B$23 -> #REF! | I23: =I22*$B$23 -> #REF! | J23: =J22*$B$23 -> #REF! | ... N23: =N22*$B$23 -> 10942200 | O23: =SUM(C23:N23) -> #REF!
A24: Public relations | B24: 0.15 | C24: =C22*$B$24 -> #REF! | D24: =D22*$B$24 -> #REF! | E24: =E22*$B$24 -> #REF! | F24: =F22*$B$24 -> #REF! | G24: =G22*$B$24 -> #REF! | H24: =H22*$B$24 -> #REF! | I24: =I22*$B$24 -> #REF! | J24: =J22*$B$24 -> #REF! | ... N24: =N22*$B$24 -> 5471100 | O24: =SUM(C24:N24) -> #REF!
A25: Sales promotion | B25: 0.15 | C25: =C22*$B$25 -> #REF! | D25: =D22*$B$25 -> #REF! | E25: =E22*$B$25 -> #REF! | F25: =F22*$B$25 -> #REF! | G25: =G22*$B$25 -> #REF! | H25: =H22*$B$25 -> #REF! | I25: =I22*$B$25 -> #REF! | J25: =J22*$B$25 -> #REF! | ... N25: =N22*$B$25 -> 5471100 | O25: =SUM(C25:N25) -> #REF!
A26: Direct marketing | B26: 0.2 | C26: =C22*$B$26 -> #REF! | D26: =D22*$B$26 -> #REF! | E26: =E22*$B$26 -> #REF! | F26: =F22*$B$26 -> #REF! | G26: =G22*$B$26 -> #REF! | H26: =H22*$B$26 -> #REF! | I26: =I22*$B$26 -> #REF! | J26: =J22*$B$26 -> #REF! | ... N26: =N22*$B$26 -> 7294800 | O26: =SUM(C26:N26) -> #REF!
A27: Personal selling | B27: 0.2 | C27: =C22*$B$27 -> #REF! | D27: =D22*$B$27 -> #REF! | E27: =E22*$B$27 -> #REF! | F27: =F22*$B$27 -> #REF! | G27: =G22*$B$27 -> #REF! | H27: =H22*$B$27 -> #REF! | I27: =I22*$B$27 -> #REF! | J27: =J22*$B$27 -> #REF! | ... N27: =N22*$B$27 -> 7294800 | O27: =SUM(C27:N27) -> #REF!
A29: Detail | B29: % Total Marketing Expenses | C29: Year 4 | O29: Full Year
C30: Jan | D30: Feb | E30: Mar | F30: Apr | G30: May | H30: Jun | I30: Jul | J30: Aug | K30: Sep | L30: Oct | M30: Nov | N30: Dec
A31: Total Marketing Expenses | C31: ='Operating Expenses'!#REF! -> #REF! | D31: ='Operating Expenses'!#REF! -> #REF! | E31: ='Operating Expenses'!#REF! -> #REF! | F31: ='Operating Expenses'!#REF! -> #REF! | G31: ='Operating Expenses'!#REF! -> #REF! | H31: ='Operating Expenses'!#REF! -> #REF! | I31: ='Operating Expenses'!#REF! -> #REF! | J31: ='Operating Expenses'!#REF! -> #REF! | ... M31: ='Operating Expenses'!#REF! -> #REF! | N31: ='Operating Expenses'!J13 -> 43729200 | O31: =SUM(C31:N31) -> #REF!
A32: Advertising | B32: 0.3 | C32: =C31*$B$32 -> #REF! | D32: =D31*$B$32 -> #REF! | E32: =E31*$B$32 -> #REF! | F32: =F31*$B$32 -> #REF! | G32: =G31*$B$32 -> #REF! | H32: =H31*$B$32 -> #REF! | I32: =I31*$B$32 -> #REF! | J32: =J31*$B$32 -> #REF! | ... N32: =N31*$B$32 -> 13118760 | O32: =SUM(C32:N32) -> #REF!
A33: Public relations | B33: 0.15 | C33: =C31*$B$33 -> #REF! | D33: =D31*$B$33 -> #REF! | E33: =E31*$B$33 -> #REF! | F33: =F31*$B$33 -> #REF! | G33: =G31*$B$33 -> #REF! | H33: =H31*$B$33 -> #REF! | I33: =I31*$B$33 -> #REF! | J33: =J31*$B$33 -> #REF! | ... N33: =N31*$B$33 -> 6559380 | O33: =SUM(C33:N33) -> #REF!
A34: Sales promotion | B34: 0.15 | C34: =C31*$B$34 -> #REF! | D34: =D31*$B$34 -> #REF! | E34: =E31*$B$34 -> #REF! | F34: =F31*$B$34 -> #REF! | G34: =G31*$B$34 -> #REF! | H34: =H31*$B$34 -> #REF! | I34: =I31*$B$34 -> #REF! | J34: =J31*$B$34 -> #REF! | ... N34: =N31*$B$34 -> 6559380 | O34: =SUM(C34:N34) -> #REF!
A35: Direct marketing | B35: 0.2 | C35: =C31*$B$35 -> #REF! | D35: =D31*$B$35 -> #REF! | E35: =E31*$B$35 -> #REF! | F35: =F31*$B$35 -> #REF! | G35: =G31*$B$35 -> #REF! | H35: =H31*$B$35 -> #REF! | I35: =I31*$B$35 -> #REF! | J35: =J31*$B$35 -> #REF! | ... N35: =N31*$B$35 -> 8745840 | O35: =SUM(C35:N35) -> #REF!
A36: Personal selling | B36: 0.2 | C36: =C31*$B$36 -> #REF! | D36: =D31*$B$36 -> #REF! | E36: =E31*$B$36 -> #REF! | F36: =F31*$B$36 -> #REF! | G36: =G31*$B$36 -> #REF! | H36: =H31*$B$36 -> #REF! | I36: =I31*$B$36 -> #REF! | J36: =J31*$B$36 -> #REF! | ... N36: =N31*$B$36 -> 8745840 | O36: =SUM(C36:N36) -> #REF!
A38: Detail | B38: % Total Marketing Expenses | C38: Year 5 | O38: Full Year
C39: Jan | D39: Feb | E39: Mar | F39: Apr | G39: May | H39: Jun | I39: Jul | J39: Aug | K39: Sep | L39: Oct | M39: Nov | N39: Dec
A40: Total Marketing Expenses | C40: ='Operating Expenses'!#REF! -> #REF! | D40: ='Operating Expenses'!#REF! -> #REF! | E40: ='Operating Expenses'!#REF! -> #REF! | F40: ='Operating Expenses'!#REF! -> #REF! | G40: ='Operating Expenses'!#REF! -> #REF! | H40: ='Operating Expenses'!#REF! -> #REF! | I40: ='Operating Expenses'!#REF! -> #REF! | J40: ='Operating Expenses'!#REF! -> #REF! | ... N40: ='Operating Expenses'!#REF! -> #REF! | O40: =SUM(C40:N40) -> #REF!
A41: Advertising | B41: 0.3 | C41: =C40*$B$41 -> #REF! | D41: =D40*$B$41 -> #REF! | E41: =E40*$B$41 -> #REF! | F41: =F40*$B$41 -> #REF! | G41: =G40*$B$41 -> #REF! | H41: =H40*$B$41 -> #REF! | I41: =I40*$B$41 -> #REF! | J41: =J40*$B$41 -> #REF! | ... N41: =N40*$B$41 -> #REF! | O41: =SUM(C41:N41) -> #REF!
A42: Public relations | B42: 0.15 | C42: =C40*$B$42 -> #REF! | D42: =D40*$B$42 -> #REF! | E42: =E40*$B$42 -> #REF! | F42: =F40*$B$42 -> #REF! | G42: =G40*$B$42 -> #REF! | H42: =H40*$B$42 -> #REF! | I42: =I40*$B$42 -> #REF! | J42: =J40*$B$42 -> #REF! | ... N42: =N40*$B$42 -> #REF! | O42: =SUM(C42:N42) -> #REF!
A43: Sales promotion | B43: 0.15 | C43: =C40*$B$43 -> #REF! | D43: =D40*$B$43 -> #REF! | E43: =E40*$B$43 -> #REF! | F43: =F40*$B$43 -> #REF! | G43: =G40*$B$43 -> #REF! | H43: =H40*$B$43 -> #REF! | I43: =I40*$B$43 -> #REF! | J43: =J40*$B$43 -> #REF! | ... N43: =N40*$B$43 -> #REF! | O43: =SUM(C43:N43) -> #REF!
A44: Direct marketing | B44: 0.2 | C44: =C40*$B$44 -> #REF! | D44: =D40*$B$44 -> #REF! | E44: =E40*$B$44 -> #REF! | F44: =F40*$B$44 -> #REF! | G44: =G40*$B$44 -> #REF! | H44: =H40*$B$44 -> #REF! | I44: =I40*$B$44 -> #REF! | J44: =J40*$B$44 -> #REF! | ... N44: =N40*$B$44 -> #REF! | O44: =SUM(C44:N44) -> #REF!
...

Sheet Salary Expenses
B2: Salary Expenses (Unit: VND)
B3: Year 1
B4: No. | C4: Position | D4: Number | E4: Basic Salary | F4: Insurance (21,5%) | G4: 13th-month bonus | H4: Year
B5: 1 | C5: CEO | D5: 1 | E5: 6000000 | F5: ='Insurance Structure'!$E$5*5310000 -> 1141650 | G5: =E5 -> 6000000 | H5: =(E5+F5)*D5*12+G5*D5 -> 91699800
B6: 2 | C6: CDO | D6: 1 | E6: 5500000 | F6: ='Insurance Structure'!$E$5*5310000 -> 1141650 | G6: =E6 -> 5500000 | H6: =(E6+F6)*D6*12+G6*D6 -> 85199800
B7: 3 | C7: CPO | D7: 1 | E7: 5500000 | F7: ='Insurance Structure'!$E$5*5310000 -> 1141650 | G7: =E7 -> 5500000 | H7: =(E7+F7)*D7*12+G7*D7 -> 85199800
B8: 4 | C8: CTO | D8: 1 | E8: 5500000 | F8: ='Insurance Structure'!$E$5*5310000 -> 1141650 | G8: =E8 -> 5500000 | H8: =(E8+F8)*D8*12+G8*D8 -> 85199800
B9: 5 | C9: CMO | D9: 1 | E9: 5500000 | F9: ='Insurance Structure'!$E$5*5310000 -> 1141650 | G9: =E9 -> 5500000 | H9: =(E9+F9)*D9*12+G9*D9 -> 85199800
B10: 6 | C10: Sales & Marketing Staff | D10: 0 | F10: ='Insurance Structure'!$E$5*5310000 -> 1141650 | G10: =E10 -> 0 | H10: =(E10+F10)*D10*12+G10*D10 -> 0
B11: 7 | C11: CFO | D11: 1 | E11: 5500000 | F11: ='Insurance Structure'!$E$5*5310000 -> 1141650 | G11: =E11 -> 5500000 | H11: =(E11+F11)*D11*12+G11*D11 -> 85199800
B12: Total | D12: =SUM(D5:D11) -> 6 | H12: =SUM(H5:H11) -> 517698800
B13: Year 2
B14: No. | C14: Position | D14: Number | E14: Basic Salary | F14: Insurance | G14: 13th-month bonus | H14: Year
B15: 1 | C15: =C5 -> CEO | D15: 1 | E15: =E5*105% -> 6300000 | F15: ='Insurance Structure'!$E$5*5310000 -> 1141650 | G15: =E15 -> 6300000 | H15: =(E15+F15)*D15*12+G15*D15 -> 95599800
B16: 2 | C16: =C6 -> CDO | D16: 1 | E16: =E6*105% -> 5775000 | F16: ='Insurance Structure'!$E$5*5310000 -> 1141650 | G16: =E16 -> 5775000 | H16: =(E16+F16)*D16*12+G16*D16 -> 88774800
B17: 3 | C17: =C7 -> CPO | D17: 1 | E17: =E7*105% -> 5775000 | F17: ='Insurance Structure'!$E$5*5310000 -> 1141650 | G17: =E17 -> 5775000 | H17: =(E17+F17)*D17*12+G17*D17 -> 88774800
B18: 4 | C18: =C8 -> CTO | D18: 1 | E18: =E8*105% -> 5775000 | F18: ='Insurance Structure'!$E$5*5310000 -> 1141650 | G18: =E18 -> 5775000 | H18: =(E18+F18)*D18*12+G18*D18 -> 88774800
B19: 5 | C19: =C9 -> CMO | D19: 1 | E19: =E9*105% -> 5775000 | F19: ='Insurance Structure'!$E$5*5310000 -> 1141650 | G19: =E19 -> 5775000 | H19: =(E19+F19)*D19*12+G19*D19 -> 88774800
B20: 6 | C20: =C10 -> Sales & Marketing Staff | D20: 1 | E20: 8000000 | F20: ='Insurance Structure'!$E$5*5310000 -> 1141650 | G20: =E20 -> 8000000 | H20: =(E20+F20)*D20*12+G20*D20 -> 117699800
B21: 7 | C21: =C11 -> CFO | D21: 1 | E21: =E11*105% -> 5775000 | F21: ='Insurance Structure'!$E$5*5310000 -> 1141650 | G21: =E21 -> 5775000 | H21: =(E21+F21)*D21*12+G21*D21 -> 88774800
B22: Total | D22: =SUM(D15:D21) -> 7 | H22: =SUM(H15:H21) -> 657173600
B23: Year 3
B24: No. | C24: Position | D24: Number | E24: Basic Salary | F24: Insurance | G24: 13th-month bonus | H24: Year
B25: 1 | C25: =C15 -> CEO | D25: 1 | E25: 10000000 | F25: ='Insurance Structure'!$E$5*5310000 -> 1141650 | G25: =E25 -> 10000000 | H25: =(E25+F25)*D25*12+G25*D25 -> 143699800
B26: 2 | C26: =C16 -> CDO | D26: 1 | E26: 8000000 | F26: ='Insurance Structure'!$E$5*5310000 -> 1141650 | G26: =E26 -> 8000000 | H26: =(E26+F26)*D26*12+G26*D26 -> 117699800
B27: 3 | C27: =C17 -> CPO | D27: 1 | E27: 8000000 | F27: ='Insurance Structure'!$E$5*5310000 -> 1141650 | G27: =E27 -> 8000000 | H27: =(E27+F27)*D27*12+G27*D27 -> 117699800
B28: 4 | C28: =C18 -> CTO | D28: 1 | E28: 8000000 | F28: ='Insurance Structure'!$E$5*5310000 -> 1141650 | G28: =E28 -> 8000000 | H28: =(E28+F28)*D28*12+G28*D28 -> 117699800
B29: 5 | C29: =C19 -> CMO | D29: 1 | E29: 8000000 | F29: ='Insurance Structure'!$E$5*5310000 -> 1141650 | G29: =E29 -> 8000000 | H29: =(E29+F29)*D29*12+G29*D29 -> 117699800
B30: 6 | C30: =C20 -> Sales & Marketing Staff | D30: 1 | E30: =E20*105% -> 8400000 | F30: ='Insurance Structure'!$E$5*5310000 -> 1141650 | G30: =E30 -> 8400000 | H30: =(E30+F30)*D30*12+G30*D30 -> 122899800
B31: 7 | C31: =C21 -> CFO | D31: 1 | E31: 8000000 | F31: ='Insurance Structure'!$E$5*5310000 -> 1141650 | G31: =E31 -> 8000000 | H31: =(E31+F31)*D31*12+G31*D31 -> 117699800
B32: Total | D32: =SUM(D25:D31) -> 7 | H32: =SUM(H25:H31) -> 855098600
B33: Year 4
B34: No. | C34: Position | D34: Number | E34: Basic Salary | F34: Insurance | G34: 13th-month bonus | H34: Year
B35: 1 | C35: =C25 -> CEO | D35: 1 | E35: 12000000 | F35: ='Insurance Structure'!$E$5*5310000 -> 1141650 | G35: =E35 -> 12000000 | H35: =(E35+F35)*D35*12+G35*D35 -> 169699800
B36: 2 | C36: =C26 -> CDO | D36: 1 | E36: 10000000 | F36: ='Insurance Structure'!$E$5*5310000 -> 1141650 | G36: =E36 -> 10000000 | H36: =(E36+F36)*D36*12+G36*D36 -> 143699800
B37: 3 | C37: =C27 -> CPO | D37: 1 | E37: 10000000 | F37: ='Insurance Structure'!$E$5*5310000 -> 1141650 | G37: =E37 -> 10000000 | H37: =(E37+F37)*D37*12+G37*D37 -> 143699800
B38: 4 | C38: =C28 -> CTO | D38: 1 | E38: 10000000 | F38: ='Insurance Structure'!$E$5*5310000 -> 1141650 | G38: =E38 -> 10000000 | H38: =(E38+F38)*D38*12+G38*D38 -> 143699800
B39: 5 | C39: =C29 -> CMO | D39: 1 | E39: 10000000 | F39: ='Insurance Structure'!$E$5*5310000 -> 1141650 | G39: =E39 -> 10000000 | H39: =(E39+F39)*D39*12+G39*D39 -> 143699800
B40: 6 | C40: =C30 -> Sales & Marketing Staff | D40: 2 | E40: =E30*105% -> 8820000 | F40: ='Insurance Structure'!$E$5*5310000 -> 1141650 | G40: =E40 -> 8820000 | H40: =(E40+F40)*D40*12+G40*D40 -> 256719600
B41: 7 | C41: =C31 -> CFO | D41: 1 | E41: 10000000 | F41: ='Insurance Structure'!$E$5*5310000 -> 1141650 | G41: =E41 -> 10000000 | H41: =(E41+F41)*D41*12+G41*D41 -> 143699800
...

Sheet Estimated Sale
B2: Estimated Sale
B4: Year1
B5: No | C5: Product | D5: Price per Unit | E5: COGS | F5: Estimated Unit Sale Per Month | G5: Total Unit Sale | H5: Total Sale | I5: Total COGS | M5: Unit Sale | N5: Total Sale
B6: 1 | C6: ='Price setting'!C4 -> Áo phông | D6: ='Price setting'!D4 -> 250000 | E6: ='Price setting'!E4 -> 118000 | F6: 483 | G6: =F6*12 -> 5796 | H6: =G6*D6 -> 1449000000 | I6: =G6*E6 -> 683928000 | L6: Year 1 | M6: =G12 -> 25524 | N6: =H12 -> 2551440000
B7: 2 | C7: ='Price setting'!C5 -> Áo hoodie | D7: ='Price setting'!D5 -> 280000 | E7: ='Price setting'!E5 -> 138000 | F7: 116 | G7: =F7*12 -> 1392 | H7: =G7*D7 -> 389760000 | I7: =G7*E7 -> 192096000 | L7: Year 2 | M7: =G22 -> 31752 | N7: =H22 -> 3175020000
B8: 3 | C8: ='Price setting'!C6 -> Móc khoá | D8: ='Price setting'!D6 -> 15000 | E8: ='Price setting'!E6 -> 9500 | F8: 809 | G8: =F8*12 -> 9708 | H8: =G8*D8 -> 145620000 | I8: =G8*E8 -> 92226000 | L8: Year 3 | M8: =G32 -> 36480 | N8: =H32 -> 3647400000
B9: 4 | C9: ='Price setting'!C7 -> Mũ | D9: ='Price setting'!D7 -> 45000 | E9: ='Price setting'!E7 -> 15500 | F9: 403 | G9: =F9*12 -> 4836 | H9: =G9*D9 -> 217620000 | I9: =G9*E9 -> 74958000 | L9: Year 4 | M9: =G42 -> 43752 | N9: =H42 -> 4372920000
B10: 5 | C10: ='Price setting'!C8 -> Tất | D10: ='Price setting'!D8 -> 20000 | E10: ='Price setting'!E8 -> 9500 | F10: 240 | G10: =F10*12 -> 2880 | H10: =G10*D10 -> 57600000 | I10: =G10*E10 -> 27360000
B11: 6 | C11: ='Price setting'!C9 -> Áo bomber | D11: ='Price setting'!D9 -> 320000 | E11: ='Price setting'!E9 -> 158000 | F11: 76 | G11: =F11*12 -> 912 | H11: =G11*D11 -> 291840000 | I11: =G11*E11 -> 144096000
B12: Total | F12: =SUM(F6:F11) -> 2127 | G12: =SUM(G6:G11) -> 25524 | H12: =SUM(H6:H11) -> 2551440000 | I12: =SUM(I6:I11) -> 1214664000
B14: Year2
B15: No | C15: Product | D15: Price per Unit | E15: COGS | F15: Estimated Unit Sale Per Month | G15: Total Unit Sale | H15: Total Sale | I15: Total COGS
B16: 1 | C16: ='Price setting'!C4 -> Áo phông | D16: =D6 -> 250000 | E16: =E6 -> 118000 | F16: 601 | G16: =F16*12 -> 7212 | H16: =G16*D16 -> 1803000000 | I16: =G16*E16 -> 851016000
B17: 2 | C17: ='Price setting'!C5 -> Áo hoodie | D17: =D7 -> 280000 | E17: =E7 -> 138000 | F17: 144 | G17: =F17*12 -> 1728 | H17: =G17*D17 -> 483840000 | I17: =G17*E17 -> 238464000
B18: 3 | C18: ='Price setting'!C6 -> Móc khoá | D18: =D8 -> 15000 | E18: =E8 -> 9500 | F18: 1006 | G18: =F18*12 -> 12072 | H18: =G18*D18 -> 181080000 | I18: =G18*E18 -> 114684000
B19: 4 | C19: ='Price setting'!C7 -> Mũ | D19: =D9 -> 45000 | E19: =E9 -> 15500 | F19: 501 | G19: =F19*12 -> 6012 | H19: =G19*D19 -> 270540000 | I19: =G19*E19 -> 93186000
B20: 5 | C20: ='Price setting'!C8 -> Tất | D20: =D10 -> 20000 | E20: =E10 -> 9500 | F20: 299 | G20: =F20*12 -> 3588 | H20: =G20*D20 -> 71760000 | I20: =G20*E20 -> 34086000
B21: 6 | C21: ='Price setting'!C9 -> Áo bomber | D21: =D11 -> 320000 | E21: =E11 -> 158000 | F21: 95 | G21: =F21*12 -> 1140 | H21: =G21*D21 -> 364800000 | I21: =G21*E21 -> 180120000
B22: Total | F22: =SUM(F16:F21) -> 2646 | G22: =SUM(G16:G21) -> 31752 | H22: =SUM(H16:H21) -> 3175020000 | I22: =SUM(I16:I21) -> 1511556000
B24: Year 3
B25: No | C25: Product | D25: Price per Unit | E25: COGS | F25: Estimated Unit Sale Per Month | G25: Total Unit Sale | H25: Total Sale | I25: Total COGS
B26: 1 | C26: ='Price setting'!C4 -> Áo phông | D26: =D6 -> 250000 | E26: =E6 -> 118000 | F26: =INT(F16*115%) -> 691 | G26: =F26*12 -> 8292 | H26: =G26*D26 -> 2073000000 | I26: =G26*E26 -> 978456000
B27: 2 | C27: ='Price setting'!C5 -> Áo hoodie | D27: =D7 -> 280000 | E27: =E7 -> 138000 | F27: =INT(F17*115%) -> 165 | G27: =F27*12 -> 1980 | H27: =G27*D27 -> 554400000 | I27: =G27*E27 -> 273240000
B28: 3 | C28: ='Price setting'!C6 -> Móc khoá | D28: =D8 -> 15000 | E28: =E8 -> 9500 | F28: =INT(F18*115%) -> 1156 | G28: =F28*12 -> 13872 | H28: =G28*D28 -> 208080000 | I28: =G28*E28 -> 131784000
B29: 4 | C29: ='Price setting'!C7 -> Mũ | D29: =D9 -> 45000 | E29: =E9 -> 15500 | F29: =INT(F19*115%) -> 576 | G29: =F29*12 -> 6912 | H29: =G29*D29 -> 311040000 | I29: =G29*E29 -> 107136000
B30: 5 | C30: ='Price setting'!C8 -> Tất | D30: =D10 -> 20000 | E30: =E10 -> 9500 | F30: =INT(F20*115%) -> 343 | G30: =F30*12 -> 4116 | H30: =G30*D30 -> 82320000 | I30: =G30*E30 -> 39102000
B31: 6 | C31: ='Price setting'!C9 -> Áo bomber | D31: =D11 -> 320000 | E31: =E11 -> 158000 | F31: =INT(F21*115%) -> 109 | G31: =F31*12 -> 1308 | H31: =G31*D31 -> 418560000 | I31: =G31*E31 -> 206664000
B32: Total | F32: =SUM(F26:F31) -> 3040 | G32: =SUM(G26:G31) -> 36480 | H32: =SUM(H26:H31) -> 3647400000 | I32: =SUM(I26:I31) -> 1736382000
B34: Year 4
B35: No | C35: Product | D35: Price per Class | E35: COGS | F35: Estimated Unit Sale Per Month | G35: Total Unit Sale | H35: Total Sale | I35: Total COGS
B36: 1 | C36: ='Price setting'!C4 -> Áo phông | D36: =D6 -> 250000 | E36: =E6 -> 118000 | F36: =INT(F26*120%) -> 829 | G36: =F36*12 -> 9948 | H36: =G36*D36 -> 2487000000 | I36: =G36*E36 -> 1173864000
B37: 2 | C37: ='Price setting'!C5 -> Áo hoodie | D37: =D7 -> 280000 | E37: =E7 -> 138000 | F37: =INT(F27*120%) -> 198 | G37: =F37*12 -> 2376 | H37: =G37*D37 -> 665280000 | I37: =G37*E37 -> 327888000
B38: 3 | C38: ='Price setting'!C6 -> Móc khoá | D38: =D8 -> 15000 | E38: =E8 -> 9500 | F38: =INT(F28*120%) -> 1387 | G38: =F38*12 -> 16644 | H38: =G38*D38 -> 249660000 | I38: =G38*E38 -> 158118000
B39: 4 | C39: ='Price setting'!C7 -> Mũ | D39: =D9 -> 45000 | E39: =E9 -> 15500 | F39: =INT(F29*120%) -> 691 | G39: =F39*12 -> 8292 | H39: =G39*D39 -> 373140000 | I39: =G39*E39 -> 128526000
B40: 5 | C40: ='Price setting'!C8 -> Tất | D40: =D10 -> 20000 | E40: =E10 -> 9500 | F40: =INT(F30*120%) -> 411 | G40: =F40*12 -> 4932 | H40: =G40*D40 -> 98640000 | I40: =G40*E40 -> 46854000
B41: 6 | C41: ='Price setting'!C9 -> Áo bomber | D41: =D11 -> 320000 | E41: =E11 -> 158000 | F41: =INT(F31*120%) -> 130 | G41: =F41*12 -> 1560 | H41: =G41*D41 -> 499200000 | I41: =G41*E41 -> 246480000
B42: Total | F42: =SUM(F36:F41) -> 3646 | G42: =SUM(G36:G41) -> 43752 | H42: =SUM(H36:H41) -> 4372920000 | I42: =SUM(I36:I41) -> 2081730000
N48: Năm | O48: Units/tháng | P48: Doanh thu/năm
N49: Year 1 | O49: 2127 | P49: ~2.55 tỷ
N50: Year 2 | O50: 2646 | P50: ~3.17 tỷ
...

Sheet Operating Expenses
B2: Operating Expense (Unit: VND)
D3: Year 1 | F3: Year 2 | H3: Year 3 | J3: Year 4
B4: No | C4: Expense | D4: Expenses per month | E4: Expenses per Year | F4: Expenses per month | G4: Total Expenses per Year | H4: Expenses per month | I4: Total Expenses per Year | J4: Expenses per month | K4: Total Expenses per Year
B5: 1 | C5: Rental Expense | D5: ='Start-Up Investment'!F32 -> 8000000 | E5: =D5*12 -> 96000000 | F5: =D5 -> 8000000 | G5: =F5*12 -> 96000000 | H5: =D5*110% -> 8800000 | I5: =H5*12 -> 105600000 | J5: =F5*110% -> 8800000 | K5: =J5*12 -> 105600000 | O5: https://vnexpress.net/gia-thue-mat-bang-ban-le-trung-tam-tp-hcm-tang-10-moi-nam-4837697.html#:~:text=Gi%C3%A1%20thu%C3%AA%20c%C3%B3%20s%E1%BB%B1%20t%C4%83ng,7%25%20so%20v%E1%BB%9Bi%20c%C3%B9ng%20k%E1%BB%B3.
B6: 2 | C6: Salary Expenses | D6: ='Salary Expenses'!H12/12 -> 43141567 | E6: =D6*12 -> 517698800 | F6: ='Salary Expenses'!H22/12 -> 54764467 | G6: =F6*12 -> 657173600 | H6: ='Salary Expenses'!H32/12 -> 71258217 | I6: =H6*12 -> 855098600 | J6: ='Salary Expenses'!H42/12 -> 95409867 | K6: =J6*12 -> 1144918400
B7: 3 | C7: Hosting | D7: 187500 | E7: =D7*12 -> 2250000 | F7: 262500 | G7: =F7*12 -> 3150000 | H7: 337500 | I7: =H7*12 -> 4050000 | J7: 415500 | K7: =J7*12 -> 4986000 | O7: https://bkhost.vn/hosting/doanh-nghiep/
B8: 4 | C8: Server | D8: 120900 | E8: =D8*12 -> 1450800 | F8: 150900 | G8: =F8*12 -> 1810800 | H8: 226900 | I8: =H8*12 -> 2722800 | J8: 453900 | K8: =J8*12 -> 5446800 | O8: https://www.hostinger.vn/?utm_campaign=Generic-Hosting|NT:Se|LO:VN&utm_medium=ppc&gad_source=1&gclid=Cj0KCQjw8MG1BhCoARIsAHxSiQnNKzCcwaNKZxk7fWqsoniL578S3Pm7du-gC_2skDFg5CB9jqgccFUaAsFmEALw_wcB
B9: 5 | C9: Supplies Expenses | D9: 1500000 | E9: =D9*12 -> 18000000 | F9: =D9*108% -> 1620000 | G9: =F9*12 -> 19440000 | H9: =F9*105% -> 1701000 | I9: =H9*12 -> 20412000 | J9: =H9*105% -> 1786050 | K9: =J9*12 -> 21432600
B10: 6 | C10: Business-license tax | E10: 2000000 | G10: 2000000 | I10: 2000000 | K10: 2000000
B11: Total Fixed cost | D11: =SUM(D5:D10) -> 52949967 | E11: =SUM(E5:E10) -> 637399600 | F11: =SUM(F5:F10) -> 64797867 | G11: =SUM(G5:G10) -> 779574400 | H11: =SUM(H5:H10) -> 82323617 | I11: =SUM(I5:I10) -> 989883400 | J11: =SUM(J5:J10) -> 1.0686532e+08 | K11: =SUM(K5:K10) -> 1284383800
B12: 1 | C12: COGS | D12: ='Estimated Sale'!I12/12 -> 101222000 | E12: =D12*12 -> 1214664000 | F12: ='Estimated Sale'!I22/12 -> 125963000 | G12: =F12*12 -> 1511556000 | H12: ='Estimated Sale'!I32/12 -> 144698500 | I12: =H12*12 -> 1736382000 | J12: ='Estimated Sale'!I42/12 -> 173477500 | K12: =J12*12 -> 2081730000
B13: 2 | C13: Marketing expense | D13: ='Estimated Sale'!H12*15%/12 -> 31893000 | E13: =D13*12 -> 382716000 | F13: ='Estimated Sale'!H22*15%/12 -> 39687750 | G13: =F13*12 -> 476253000 | H13: ='Estimated Sale'!H32*12%/12 -> 36474000 | I13: =H13*12 -> 437688000 | J13: ='Estimated Sale'!H42*12%/12 -> 43729200 | K13: =J13*12 -> 524750400
B14: 3 | C14: Other expense | D14: 1200000 | E14: =D14*12 -> 14400000 | F14: =D14*105% -> 1260000 | G14: =F14*12 -> 15120000 | H14: =F14*105% -> 1323000 | I14: =H14*12 -> 15876000 | J14: =H14*105% -> 1389150 | K14: =J14*12 -> 16669800
B15: Total Variable cost | D15: =SUM(D12:D14) -> 134315000 | E15: =SUM(E12:E14) -> 1611780000 | F15: =SUM(F12:F14) -> 166910750 | G15: =SUM(G12:G14) -> 2002929000 | H15: =SUM(H12:H14) -> 182495500 | I15: =SUM(I12:I14) -> 2189946000 | J15: =SUM(J12:J14) -> 218595850 | K15: =SUM(K12:K14) -> 2623150200

Sheet Operating Expenses -Year
B2: Fixed cost (Unit: VND)
B3: No | C3: Expense | D3: Year 1 | E3: Year 2 | F3: Year 3 | G3: Year 4
B4: 1 | C4: ='Operating Expenses'!C5 -> Rental Expense | D4: ='Operating Expenses'!E5 -> 96000000 | E4: ='Operating Expenses'!G5 -> 96000000 | F4: ='Operating Expenses'!I5 -> 105600000 | G4: ='Operating Expenses'!K5 -> 105600000
B5: 4 | C5: ='Operating Expenses'!C6 -> Salary Expenses | D5: ='Operating Expenses'!E6 -> 517698800 | E5: ='Operating Expenses'!G6 -> 657173600 | F5: ='Operating Expenses'!I6 -> 855098600 | G5: ='Operating Expenses'!K6 -> 1144918400
B6: 5 | C6: ='Operating Expenses'!C7 -> Hosting | D6: ='Operating Expenses'!E7 -> 2250000 | E6: ='Operating Expenses'!G7 -> 3150000 | F6: ='Operating Expenses'!I7 -> 4050000 | G6: ='Operating Expenses'!K7 -> 4986000
B7: 6 | C7: ='Operating Expenses'!C8 -> Server | D7: ='Operating Expenses'!E8 -> 1450800 | E7: ='Operating Expenses'!G8 -> 1810800 | F7: ='Operating Expenses'!I8 -> 2722800 | G7: ='Operating Expenses'!K8 -> 5446800
B8: 7 | C8: ='Operating Expenses'!C9 -> Supplies Expenses | D8: ='Operating Expenses'!E9 -> 18000000 | E8: ='Operating Expenses'!G9 -> 19440000 | F8: ='Operating Expenses'!I9 -> 20412000 | G8: ='Operating Expenses'!K9 -> 21432600
B9: 8 | C9: ='Operating Expenses'!C10 -> Business-license tax | D9: ='Operating Expenses'!E10 -> 2000000 | E9: ='Operating Expenses'!G10 -> 2000000 | F9: ='Operating Expenses'!I10 -> 2000000 | G9: ='Operating Expenses'!K10 -> 2000000
B13: Variable cost (Unit: VND)
B14: No | C14: Expense | D14: Year 1 | E14: Year 2 | F14: Year 3 | G14: Year 4
B15: 1 | C15: ='Operating Expenses'!C12 -> COGS | D15: ='Operating Expenses'!E12 -> 1214664000 | E15: ='Operating Expenses'!G12 -> 1511556000 | F15: ='Operating Expenses'!I12 -> 1736382000 | G15: ='Operating Expenses'!K12 -> 2081730000
B16: 3 | C16: ='Operating Expenses'!C13 -> Marketing expense | D16: ='Operating Expenses'!E13 -> 382716000 | E16: ='Operating Expenses'!G13 -> 476253000 | F16: ='Operating Expenses'!I13 -> 437688000 | G16: ='Operating Expenses'!K13 -> 524750400
B17: 4 | C17: ='Operating Expenses'!C14 -> Other expense | D17: ='Operating Expenses'!E14 -> 14400000 | E17: ='Operating Expenses'!G14 -> 15120000 | F17: ='Operating Expenses'!I14 -> 15876000 | G17: ='Operating Expenses'!K14 -> 16669800
E20: Total Fixed cost | F20: Total Variable cost
D21: Year 1 | E21: ='Operating Expenses'!E11 -> 637399600 | F21: =SUM(D15:D17) -> 1611780000
D22: Year 2 | E22: ='Operating Expenses'!G11 -> 779574400 | F22: =SUM(E15:E17) -> 2002929000
D23: Year 3 | E23: ='Operating Expenses'!I11 -> 989883400 | F23: =SUM(F15:F17) -> 2189946000
D24: Year 4 | E24: ='Operating Expenses'!K11 -> 1284383800 | F24: =SUM(G15:G17) -> 2623150200

Sheet Estimated Annual Cash Flow
B2: Estimated Cash Flow (Unit: VND)
C3: 0 | D3: 2026 | E3: 2027 | F3: 2028 | G3: 2029
B4: Sales | D4: ='Estimated Income - Year'!C4 -> 2551440000 | E4: ='Estimated Income - Year'!D4 -> 3175020000 | F4: ='Estimated Income - Year'!E4 -> 3647400000 | G4: ='Estimated Income - Year'!F4 -> 4372920000
B5: Fixed Cost | D5: =SUM(D6:D11) -> -637399600 | E5: =SUM(E6:E11) -> -779574400 | F5: =SUM(F6:F11) -> -989883400 | G5: =SUM(G6:G11) -> -1284383800
B6: ='Operating Expenses'!C5 -> Rental Expense | D6: =-'Estimated Income - Year'!C9 -> -96000000 | E6: =-'Estimated Income - Year'!D9 -> -96000000 | F6: =-'Estimated Income - Year'!E9 -> -105600000 | G6: =-'Estimated Income - Year'!F9 -> -105600000
B7: ='Operating Expenses'!C6 -> Salary Expenses | D7: =-'Estimated Income - Year'!C10 -> -517698800 | E7: =-'Estimated Income - Year'!D10 -> -657173600 | F7: =-'Estimated Income - Year'!E10 -> -855098600 | G7: =-'Estimated Income - Year'!F10 -> -1144918400
B8: ='Operating Expenses'!C7 -> Hosting | D8: =-'Estimated Income - Year'!C11 -> -2250000 | E8: =-'Estimated Income - Year'!D11 -> -3150000 | F8: =-'Estimated Income - Year'!E11 -> -4050000 | G8: =-'Estimated Income - Year'!F11 -> -4986000
B9: ='Operating Expenses'!C8 -> Server | D9: =-'Estimated Income - Year'!C12 -> -1450800 | E9: =-'Estimated Income - Year'!D12 -> -1810800 | F9: =-'Estimated Income - Year'!E12 -> -2722800 | G9: =-'Estimated Income - Year'!F12 -> -5446800
B10: ='Operating Expenses'!C9 -> Supplies Expenses | D10: =-'Estimated Income - Year'!C13 -> -18000000 | E10: =-'Estimated Income - Year'!D13 -> -19440000 | F10: =-'Estimated Income - Year'!E13 -> -20412000 | G10: =-'Estimated Income - Year'!F13 -> -21432600
B11: ='Operating Expenses'!C10 -> Business-license tax | D11: =-'Estimated Income - Year'!C14 -> -2000000 | E11: =-'Estimated Income - Year'!D14 -> -2000000 | F11: =-'Estimated Income - Year'!E14 -> -2000000 | G11: =-'Estimated Income - Year'!F14 -> -2000000
B12: Variable Cost | D12: =SUM(D13:D15) -> -1611780000 | E12: =SUM(E13:E15) -> -2002929000 | F12: =SUM(F13:F15) -> -2189946000 | G12: =SUM(G13:G15) -> -2623150200
B13: COGS | D13: =-'Estimated Income - Year'!C6 -> -1214664000 | E13: =-'Estimated Income - Year'!D6 -> -1511556000 | F13: =-'Estimated Income - Year'!E6 -> -1736382000 | G13: =-'Estimated Income - Year'!F6 -> -2081730000
B14: ='Operating Expenses'!C13 -> Marketing expense | D14: =-'Estimated Income - Year'!C15 -> -382716000 | E14: =-'Estimated Income - Year'!D15 -> -476253000 | F14: =-'Estimated Income - Year'!E15 -> -437688000 | G14: =-'Estimated Income - Year'!F15 -> -524750400
B15: ='Operating Expenses'!C14 -> Other expense | D15: =-'Estimated Income - Year'!C16 -> -14400000 | E15: =-'Estimated Income - Year'!D16 -> -15120000 | F15: =-'Estimated Income - Year'!E16 -> -15876000 | G15: =-'Estimated Income - Year'!F16 -> -16669800
B16: EBITDA | D16: =D4+D5+D12 -> 302260400 | E16: =E4+E5+E12 -> 392516600 | F16: =F4+F5+F12 -> 467570600 | G16: =G4+G5+G12 -> 465386000
B17: Depreciation and allocation expenses | D17: =-'Estimated Income - Year'!C17 -> -24583333 | E17: =-'Estimated Income - Year'!D17 -> -23833333 | F17: =-'Estimated Income - Year'!E17 -> -14583333 | G17: =-'Estimated Income - Year'!F17 -> 0
B18: EBIT = EBITDA - D&A | D18: =D16+D17 -> 2.7767707e+08 | E18: =E16+E17 -> 3.6868327e+08 | F18: =F16+F17 -> 4.5298727e+08 | G18: =G16+G17 -> 465386000
B19: Interest Expenses | D19: 0 | E19: 0 | F19: 0 | G19: 0
B20: EBT | D20: =D18+D19 -> 2.7767707e+08 | E20: =E18+E19 -> 3.6868327e+08 | F20: =F18+F19 -> 4.5298727e+08 | G20: =G18+G19 -> 465386000
B21: Corporate income tax | D21: =-'Estimated Income - Year'!C19 -> -55535413 | E21: =-'Estimated Income - Year'!D19 -> -73736653 | F21: =-'Estimated Income - Year'!E19 -> -90597453 | G21: =-'Estimated Income - Year'!F19 -> -93077200
B22: Net operating profit after tax | D22: =SUM(D20:D21) -> 2.2214165e+08 | E22: =SUM(E20:E21) -> 2.9494661e+08 | F22: =SUM(F20:F21) -> 3.6238981e+08 | G22: =SUM(G20:G21) -> 372308800
B23: Plus: Depreciation and allocation expenses | D23: =-D17 -> 24583333 | E23: =-E17 -> 23833333 | F23: =-F17 -> 14583333 | G23: =-G17 -> 0
B24: Cash Flow From Operations | D24: =D22+D23 -> 2.4672499e+08 | E24: =E22+E23 -> 3.1877995e+08 | F24: =F22+F23 -> 3.7697315e+08 | G24: =G22+G23 -> 372308800
B25: Less: Capital Expenditure | C25: =-'Start-Up Investment'!G14 -> -63000000
B26: Less: Change in Working capital | C26: =-'Start-Up Investment'!G19 -> -205000000
B27: Less: Other Investment | C27: =-'Start-Up Investment'!G33 -> -25267000
B28: Free Cash Flow | C28: =SUM(C25:C27) -> -293267000 | D28: =SUM(D24:D27) -> 2.4672499e+08 | E28: =SUM(E24:E27) -> 3.1877995e+08 | F28: =SUM(F24:F27) -> 3.7697315e+08 | G28: =SUM(G24:G27) -> 372308800
B29: Remind cost | C29: =C28 -> -293267000 | D29: =D28+C29 -> -46542013 | E29: =E28+D29 -> 2.7223793e+08 | F29: =F28+E29 -> 649211080 | G29: =G28+F29 -> 1021519880
B30: PAYBACK PERIOD (year) | C30: =-D29/E28+1 -> 1.1460004

Sheet Break Even Point
B2: Break even point | E2: Break even point
B3: Total Unit Sale | C3: ='Estimated Sale'!G42 -> 43752 | E3: Unit Sale | F3: Expenses | G3: Sale
B4: Total Sales | C4: ='Estimated Annual Cash Flow'!$G$4 -> 4372920000 | E4: 0 | F4: =C5 -> 1284383800 | G4: =E4*$C$7 -> 0
B5: Total Fixed Cost | C5: =-'Estimated Annual Cash Flow'!$G$5 -> 1284383800 | E5: =E4+2000 -> 2000 | F5: =$C$5+$C$8*E5 -> 1.4042938e+09 | G5: =E5*$C$7 -> 1.9989578e+08
B6: Total Variable Cost | C6: =-'Estimated Annual Cash Flow'!$G$12 -> 2623150200 | E6: =E5+2000 -> 4000 | F6: =$C$5+$C$8*E6 -> 1.5242037e+09 | G6: =E6*$C$7 -> 3.9979155e+08
B7: Average price per unit | C7: =C4/C3 -> 99947.888 | E7: =E6+2000 -> 6000 | F7: =$C$5+$C$8*E7 -> 1.6441137e+09 | G7: =E7*$C$7 -> 5.9968733e+08
B8: Average Variable Cost per unit | C8: =C6/C3 -> 59954.978 | E8: =E7+2000 -> 8000 | F8: =$C$5+$C$8*E8 -> 1.7640236e+09 | G8: =E8*$C$7 -> 7.995831e+08
B9: Break Even Point | C9: =C5/(C7-C8) -> 32115.287 | E9: =E8+2000 -> 10000 | F9: =$C$5+$C$8*E9 -> 1.8839336e+09 | G9: =E9*$C$7 -> 9.9947888e+08
E10: =E9+2000 -> 12000 | F10: =$C$5+$C$8*E10 -> 2.0038435e+09 | G10: =E10*$C$7 -> 1.1993747e+09
E11: =E10+2000 -> 14000 | F11: =$C$5+$C$8*E11 -> 2.1237535e+09 | G11: =E11*$C$7 -> 1.3992704e+09
E12: =E11+2000 -> 16000 | F12: =$C$5+$C$8*E12 -> 2.2436634e+09 | G12: =E12*$C$7 -> 1.5991662e+09
E13: =E12+2000 -> 18000 | F13: =$C$5+$C$8*E13 -> 2.3635734e+09 | G13: =E13*$C$7 -> 1.799062e+09
E14: =E13+2000 -> 20000 | F14: =$C$5+$C$8*E14 -> 2.4834834e+09 | G14: =E14*$C$7 -> 1.9989578e+09
E15: =E14+2000 -> 22000 | F15: =$C$5+$C$8*E15 -> 2.6033933e+09 | G15: =E15*$C$7 -> 2.1988535e+09
E16: =E15+2000 -> 24000 | F16: =$C$5+$C$8*E16 -> 2.7233033e+09 | G16: =E16*$C$7 -> 2.3987493e+09
E17: =E16+2000 -> 26000 | F17: =$C$5+$C$8*E17 -> 2.8432132e+09 | G17: =E17*$C$7 -> 2.5986451e+09
E18: =E17+2000 -> 28000 | F18: =$C$5+$C$8*E18 -> 2.9631232e+09 | G18: =E18*$C$7 -> 2.7985409e+09
E19: =E18+2000 -> 30000 | F19: =$C$5+$C$8*E19 -> 3.0830331e+09 | G19: =E19*$C$7 -> 2.9984366e+09
E20: =E19+2000 -> 32000 | F20: =$C$5+$C$8*E20 -> 3.2029431e+09 | G20: =E20*$C$7 -> 3.1983324e+09

Sheet Estimated Income - Year
B2: Estimated P&L
C3: 2026 | D3: 2027 | E3: 2028 | F3: 2029
B4: Sale | C4: ='Estimated Sale'!H12 -> 2551440000 | D4: ='Estimated Sale'!H22 -> 3175020000 | E4: ='Estimated Sale'!H32 -> 3647400000 | F4: ='Estimated Sale'!H42 -> 4372920000
B5: Sale growth | D5: =D4/C4-1 -> 0.24440316 | E5: =E4/D4-1 -> 0.14878017 | F5: =F4/E4-1 -> 0.1989143
B6: COGS | C6: ='Operating Expenses -Year'!D15 -> 1214664000 | D6: ='Operating Expenses -Year'!E15 -> 1511556000 | E6: ='Operating Expenses -Year'!F15 -> 1736382000 | F6: ='Operating Expenses -Year'!G15 -> 2081730000
B7: Gross Profit | C7: =C4-C6 -> 1336776000 | D7: =D4-D6 -> 1663464000 | E7: =E4-E6 -> 1911018000 | F7: =F4-F6 -> 2291190000
B8: Operating expense | C8: =SUM(C9:C17) -> 1.0590989e+09 | D8: =SUM(D9:D17) -> 1.2947807e+09 | E8: =SUM(E9:E17) -> 1.4580307e+09 | F8: =SUM(F9:F17) -> 1825804000
B9: ='Operating Expenses -Year'!C4 -> Rental Expense | C9: ='Operating Expenses -Year'!D4 -> 96000000 | D9: ='Operating Expenses -Year'!E4 -> 96000000 | E9: ='Operating Expenses -Year'!F4 -> 105600000 | F9: ='Operating Expenses -Year'!G4 -> 105600000
B10: ='Operating Expenses -Year'!C5 -> Salary Expenses | C10: ='Operating Expenses -Year'!D5 -> 517698800 | D10: ='Operating Expenses -Year'!E5 -> 657173600 | E10: ='Operating Expenses -Year'!F5 -> 855098600 | F10: ='Operating Expenses -Year'!G5 -> 1144918400
B11: ='Operating Expenses -Year'!C6 -> Hosting | C11: ='Operating Expenses -Year'!D6 -> 2250000 | D11: ='Operating Expenses -Year'!E6 -> 3150000 | E11: ='Operating Expenses -Year'!F6 -> 4050000 | F11: ='Operating Expenses -Year'!G6 -> 4986000
B12: ='Operating Expenses -Year'!C7 -> Server | C12: ='Operating Expenses -Year'!D7 -> 1450800 | D12: ='Operating Expenses -Year'!E7 -> 1810800 | E12: ='Operating Expenses -Year'!F7 -> 2722800 | F12: ='Operating Expenses -Year'!G7 -> 5446800
B13: ='Operating Expenses -Year'!C8 -> Supplies Expenses | C13: ='Operating Expenses -Year'!D8 -> 18000000 | D13: ='Operating Expenses -Year'!E8 -> 19440000 | E13: ='Operating Expenses -Year'!F8 -> 20412000 | F13: ='Operating Expenses -Year'!G8 -> 21432600
B14: ='Operating Expenses -Year'!C9 -> Business-license tax | C14: ='Operating Expenses -Year'!D9 -> 2000000 | D14: ='Operating Expenses -Year'!E9 -> 2000000 | E14: ='Operating Expenses -Year'!F9 -> 2000000 | F14: ='Operating Expenses -Year'!G9 -> 2000000
B15: ='Operating Expenses -Year'!C16 -> Marketing expense | C15: ='Operating Expenses -Year'!D16 -> 382716000 | D15: ='Operating Expenses -Year'!E16 -> 476253000 | E15: ='Operating Expenses -Year'!F16 -> 437688000 | F15: ='Operating Expenses -Year'!G16 -> 524750400
B16: ='Operating Expenses -Year'!C17 -> Other expense | C16: ='Operating Expenses -Year'!D17 -> 14400000 | D16: ='Operating Expenses -Year'!E17 -> 15120000 | E16: ='Operating Expenses -Year'!F17 -> 15876000 | F16: ='Operating Expenses -Year'!G17 -> 16669800
B17: Depreciation and allocation expenses | C17: ='Depreciation Expenses'!G14 -> 24583333 | D17: ='Depreciation Expenses'!H14 -> 23833333 | E17: ='Depreciation Expenses'!I14 -> 14583333 | F17: ='Depreciation Expenses'!J14 -> 0
B18: EBT | C18: =C7-C8 -> 2.7767707e+08 | D18: =D7-D8 -> 3.6868327e+08 | E18: =E7-E8 -> 4.5298727e+08 | F18: =F7-F8 -> 465386000
B19: Corporate income tax | C19: =IF(C18>0,C18*20%,0) -> 55535413 | D19: =IF(D18>0,D18*20%,0) -> 73736653 | E19: =IF(E18>0,E18*20%,0) -> 90597453 | F19: =IF(F18>0,F18*20%,0) -> 93077200
B20: Net Income | C20: =C18-C19 -> 2.2214165e+08 | D20: =D18-D19 -> 2.9494661e+08 | E20: =E18-E19 -> 3.6238981e+08 | F20: =F18-F19 -> 372308800
B21: Net Profit Margin | C21: =C20/C4 -> 0.087065208 | D21: =D20/D4 -> 0.092895986 | E21: =E20/E4 -> 0.099355654 | F21: =F20/F4 -> 0.085139632
